<?xml version="1.0" ?>
<!--
  由 myam_sys_moveit 链路的 myam_sys.xacro 经 generate_myuam_sdf.py 生成（gz sdf -p），
  关节/欧拉与独立 Gazebo 中 MoveIt 用 URDF 一致。勿手改关节 pose；改 xacro 后重新运行脚本。
  myam_description meshes: file:///home/demo/test_ws/src/myam_description/meshes/
  roarm meshes: file:///home/demo/test_ws/src/roarm_description/meshes/roarm_m3/
-->
<sdf version='1.7'>
  <model name='myuam'>
    <link name='base_link'>
      <inertial>
        <pose>0.021926 -0.000505 -0.114047 0 -0 0</pose>
        <mass>2.72224</mass>
        <inertia>
          <ixx>0.0225028</ixx>
          <ixy>0.000475773</ixy>
          <ixz>0.00629701</ixz>
          <iyy>0.0396005</iyy>
          <iyz>-0.000287749</iyz>
          <izz>0.0310396</izz>
        </inertia>
      </inertial>
      <collision name='base_link_fixed_joint_lump__base_link_collision'>
        <pose>0 0 0 0 -0 0</pose>
        <geometry>
          <mesh>
            <scale>1 1 1</scale>
            <uri>file:///home/demo/test_ws/src/myam_description/meshes/base_link.STL</uri>
          </mesh>
        </geometry>
        <!-- 机腹大网格不显式写摩擦：复杂网格蹭地时多点接触易引入净偏航力矩；摩擦由起落架统一约束 -->
      </collision>
      <collision name='base_link_fixed_joint_lump__roarm_base_link_collision_1'>
        <pose>0.073168 -0.002113 -0.2185 3.14159 0 0.000221</pose>
        <geometry>
          <mesh>
            <scale>0.001 0.001 0.001</scale>
            <uri>file:///home/demo/test_ws/src/roarm_description/meshes/roarm_m3/base_link.stl</uri>
          </mesh>
        </geometry>
      </collision>
      <collision name='base_link_fixed_joint_lump__battery_link_collision_2'>
        <pose>-0.061817 -2.3e-05 -0.068921 0 -0 0</pose>
        <geometry>
          <mesh>
            <scale>1 1 1</scale>
            <uri>file:///home/demo/test_ws/src/myam_description/meshes/battery_link.STL</uri>
          </mesh>
        </geometry>
      </collision>
      <collision name='base_link_fixed_joint_lump__camera_link_collision_3'>
        <pose>0.1675 -0.005 -0.158 0 1.5708 0</pose>
        <geometry>
          <box>
            <size>0.02505 0.09 0.025</size>
          </box>
        </geometry>
      </collision>
      <collision name='base_link_fixed_joint_lump__gps_link_collision_4'>
        <pose>-0.000407 1.3e-05 0.17697 0 -0 0</pose>
        <geometry>
          <mesh>
            <scale>1 1 1</scale>
            <uri>file:///home/demo/test_ws/src/myam_description/meshes/gps_link.STL</uri>
          </mesh>
        </geometry>
      </collision>
      <collision name='base_link_fixed_joint_lump__imu_link_collision_5'>
        <pose>-0.095599 4.1e-05 -0.013807 0 -0 0</pose>
        <geometry>
          <mesh>
            <scale>1 1 1</scale>
            <uri>file:///home/demo/test_ws/src/myam_description/meshes/imu_link.STL</uri>
          </mesh>
        </geometry>
      </collision>
      <collision name='base_link_fixed_joint_lump__landing_gear_1_link_collision_6'>
        <pose>-1.3e-05 0.21064 -0.40283 0 -0 0</pose>
        <geometry>
          <mesh>
            <scale>1 1 1</scale>
            <uri>file:///home/demo/test_ws/src/myam_description/meshes/landing_gear_1_link.STL</uri>
          </mesh>
        </geometry>
        <!-- 仅起落架显式摩擦；左右须完全一致。略降 mu + 软 kp/kd，减轻粘滑引起的偏航 -->
        <surface>
          <contact>
            <ode>
              <kp>8e4</kp>
              <kd>60</kd>
              <max_vel>0.8</max_vel>
              <min_depth>0.003</min_depth>
            </ode>
          </contact>
          <friction>
            <ode>
              <mu>3.0</mu>
              <mu2>3.0</mu2>
            </ode>
          </friction>
        </surface>
      </collision>
      <collision name='base_link_fixed_joint_lump__landing_gear_2_link_collision_7'>
        <pose>-1.3e-05 -0.21064 -0.40283 0 -0 0</pose>
        <geometry>
          <mesh>
            <scale>1 1 1</scale>
            <uri>file:///home/demo/test_ws/src/myam_description/meshes/landing_gear_2_link.STL</uri>
          </mesh>
        </geometry>
        <surface>
          <contact>
            <ode>
              <kp>8e4</kp>
              <kd>60</kd>
              <max_vel>0.8</max_vel>
              <min_depth>0.003</min_depth>
            </ode>
          </contact>
          <friction>
            <ode>
              <mu>3.0</mu>
              <mu2>3.0</mu2>
            </ode>
          </friction>
        </surface>
      </collision>
      <visual name='base_link_fixed_joint_lump__base_link_visual'>
        <pose>0 0 0 0 -0 0</pose>
        <geometry>
          <mesh>
            <scale>1 1 1</scale>
            <uri>file:///home/demo/test_ws/src/myam_description/meshes/base_link.STL</uri>
          </mesh>
        </geometry>
      </visual>
      <visual name='base_link_fixed_joint_lump__roarm_base_link_visual_1'>
        <pose>0.073168 -0.002113 -0.2185 3.14159 0 0.000221</pose>
        <geometry>
          <mesh>
            <scale>0.001 0.001 0.001</scale>
            <uri>file:///home/demo/test_ws/src/roarm_description/meshes/roarm_m3/base_link.stl</uri>
          </mesh>
        </geometry>
        <material>
          <script>
            <name>Gazebo/Silver</name>
            <uri>file://media/materials/scripts/gazebo.material</uri>
          </script>
        </material>
      </visual>
      <visual name='base_link_fixed_joint_lump__battery_link_visual_2'>
        <pose>-0.061817 -2.3e-05 -0.068921 0 -0 0</pose>
        <geometry>
          <mesh>
            <scale>1 1 1</scale>
            <uri>file:///home/demo/test_ws/src/myam_description/meshes/battery_link.STL</uri>
          </mesh>
        </geometry>
      </visual>
      <visual name='base_link_fixed_joint_lump__camera_link_visual_3'>
        <pose>0.1675 -0.005 -0.1729 -3.14159 0 1.5708</pose>
        <geometry>
          <mesh>
            <scale>1 1 1</scale>
            <uri>file:///home/demo/test_ws/src/myam_description/meshes/realsense_d435.stl</uri>
          </mesh>
        </geometry>
      </visual>
      <visual name='base_link_fixed_joint_lump__gps_link_visual_4'>
        <pose>-0.000407 1.3e-05 0.17697 0 -0 0</pose>
        <geometry>
          <mesh>
            <scale>1 1 1</scale>
            <uri>file:///home/demo/test_ws/src/myam_description/meshes/gps_link.STL</uri>
          </mesh>
        </geometry>
      </visual>
      <visual name='base_link_fixed_joint_lump__imu_link_visual_5'>
        <pose>-0.095599 4.1e-05 -0.013807 0 -0 0</pose>
        <geometry>
          <mesh>
            <scale>1 1 1</scale>
            <uri>file:///home/demo/test_ws/src/myam_description/meshes/imu_link.STL</uri>
          </mesh>
        </geometry>
      </visual>
      <visual name='base_link_fixed_joint_lump__landing_gear_1_link_visual_6'>
        <pose>-1.3e-05 0.21064 -0.40283 0 -0 0</pose>
        <geometry>
          <mesh>
            <scale>1 1 1</scale>
            <uri>file:///home/demo/test_ws/src/myam_description/meshes/landing_gear_1_link.STL</uri>
          </mesh>
        </geometry>
      </visual>
      <visual name='base_link_fixed_joint_lump__landing_gear_2_link_visual_7'>
        <pose>-1.3e-05 -0.21064 -0.40283 0 -0 0</pose>
        <geometry>
          <mesh>
            <scale>1 1 1</scale>
            <uri>file:///home/demo/test_ws/src/myam_description/meshes/landing_gear_2_link.STL</uri>
          </mesh>
        </geometry>
      </visual>
      <self_collide>0</self_collide>
      <gravity>1</gravity>
      <self_collide>0</self_collide>
      <enable_wind>0</enable_wind>
      <kinematic>0</kinematic>
      <gravity>1</gravity>
      <sensor name='camera_color' type='camera'>
        <camera name='camera'>
          <horizontal_fov>1.21126</horizontal_fov>
          <image>
            <width>640</width>
            <height>480</height>
            <format>RGB_INT8</format>
          </image>
          <clip>
            <near>0.1</near>
            <far>100</far>
          </clip>
          <noise>
            <type>gaussian</type>
            <mean>0</mean>
            <stddev>0.007</stddev>
          </noise>
        </camera>
        <always_on>1</always_on>
        <update_rate>20</update_rate>
        <visualize>0</visualize>
        <pose>0.1675 0.0125 -0.158 3.14159 1.57079 3.14159</pose>
      </sensor>
      <sensor name='camera_ired1' type='camera'>
        <camera name='camera'>
          <horizontal_fov>1.48702</horizontal_fov>
          <image>
            <width>320</width>
            <height>240</height>
            <format>L_INT8</format>
          </image>
          <clip>
            <near>0.1</near>
            <far>100</far>
          </clip>
          <noise>
            <type>gaussian</type>
            <mean>0</mean>
            <stddev>0.05</stddev>
          </noise>
        </camera>
        <always_on>0</always_on>
        <update_rate>5</update_rate>
        <visualize>0</visualize>
        <pose>0.1675 0.0125 -0.158 3.14159 1.57079 3.14159</pose>
      </sensor>
      <sensor name='camera_ired2' type='camera'>
        <camera name='camera'>
          <horizontal_fov>1.48702</horizontal_fov>
          <image>
            <width>320</width>
            <height>240</height>
            <format>L_INT8</format>
          </image>
          <clip>
            <near>0.1</near>
            <far>100</far>
          </clip>
          <noise>
            <type>gaussian</type>
            <mean>0</mean>
            <stddev>0.05</stddev>
          </noise>
        </camera>
        <always_on>0</always_on>
        <update_rate>5</update_rate>
        <visualize>0</visualize>
        <pose>0.1675 0.0125 -0.158 3.14159 1.57079 3.14159</pose>
      </sensor>
      <sensor name='camera_depth' type='depth'>
        <camera name='camera'>
          <horizontal_fov>1.48702</horizontal_fov>
          <image>
            <width>640</width>
            <height>480</height>
          </image>
          <clip>
            <near>0.1</near>
            <far>100</far>
          </clip>
          <noise>
            <type>gaussian</type>
            <mean>0</mean>
            <stddev>0.1</stddev>
          </noise>
        </camera>
        <always_on>1</always_on>
        <update_rate>20</update_rate>
        <visualize>0</visualize>
        <pose>0.1675 0.0125 -0.158 3.14159 1.57079 3.14159</pose>
      </sensor>
    </link>
    <joint name='base_link_to_link1' type='revolute'>
      <pose relative_to='base_link'>0.073168 -0.002113 -0.2185 3.14159 0 0.000221</pose>
      <parent>base_link</parent>
      <child>link1</child>
      <axis>
        <xyz>0 0 1</xyz>
        <initial_position>0</initial_position>
        <limit>
          <lower>-3.1416</lower>
          <upper>3.1416</upper>
          <effort>2.8</effort>
          <velocity>2.2</velocity>
        </limit>
        <dynamics>
          <damping>0.001</damping>
          <friction>0.001</friction>
          <spring_reference>0</spring_reference>
          <spring_stiffness>0</spring_stiffness>
        </dynamics>
      </axis>
    </joint>
    <link name='link1'>
      <pose relative_to='base_link_to_link1'>0 0 0 0 -0 0</pose>
      <inertial>
        <pose>0 0 0.037 0 -0 0</pose>
        <mass>0.0729177</mass>
        <inertia>
          <ixx>4.68465e-05</ixx>
          <ixy>0</ixy>
          <ixz>0</ixz>
          <iyy>3.32107e-05</iyy>
          <iyz>0</iyz>
          <izz>5.01023e-05</izz>
        </inertia>
      </inertial>
      <collision name='link1_collision'>
        <pose>0 0 0 0 -0 0</pose>
        <geometry>
          <mesh>
            <scale>0.001 0.001 0.001</scale>
            <uri>file:///home/demo/test_ws/src/roarm_description/meshes/roarm_m3/link1.stl</uri>
          </mesh>
        </geometry>
        <surface>
          <contact>
            <ode/>
          </contact>
          <friction>
            <ode>
              <mu>0.2</mu>
              <mu2>0.2</mu2>
            </ode>
          </friction>
        </surface>
      </collision>
      <visual name='link1_visual'>
        <pose>0 0 0 0 -0 0</pose>
        <geometry>
          <mesh>
            <scale>0.001 0.001 0.001</scale>
            <uri>file:///home/demo/test_ws/src/roarm_description/meshes/roarm_m3/link1.stl</uri>
          </mesh>
        </geometry>
        <material>
          <script>
            <name>Gazebo/Silver</name>
            <uri>file://media/materials/scripts/gazebo.material</uri>
          </script>
        </material>
      </visual>
      <self_collide>0</self_collide>
    </link>
    <joint name='link1_to_link2' type='revolute'>
      <pose relative_to='link1'>0 0 0.051959 1.57079 -1.57079 3.14159</pose>
      <parent>link1</parent>
      <child>link2</child>
      <axis>
        <xyz>0 0 1</xyz>
        <initial_position>1.05</initial_position>
        <limit>
          <lower>-1.5708</lower>
          <upper>1.5708</upper>
          <effort>2.8</effort>
          <velocity>2</velocity>
        </limit>
        <dynamics>
          <damping>0.001</damping>
          <friction>0.001</friction>
          <spring_reference>0</spring_reference>
          <spring_stiffness>0</spring_stiffness>
        </dynamics>
      </axis>
    </joint>
    <link name='link2'>
      <pose relative_to='link1_to_link2'>0 0 0 0 -0 0</pose>
      <inertial>
        <pose>0.119 0.012247 -0.0001 0 -0 0</pose>
        <mass>0.0703216</mass>
        <inertia>
          <ixx>5.46501e-05</ixx>
          <ixy>0</ixy>
          <ixz>0</ixz>
          <iyy>0.000423091</iyy>
          <iyz>0</iyz>
          <izz>0.000404557</izz>
        </inertia>
      </inertial>
      <collision name='link2_collision'>
        <pose>0 0 0 0 -0 0</pose>
        <geometry>
          <mesh>
            <scale>0.001 0.001 0.001</scale>
            <uri>file:///home/demo/test_ws/src/roarm_description/meshes/roarm_m3/link2.stl</uri>
          </mesh>
        </geometry>
        <surface>
          <contact>
            <ode/>
          </contact>
          <friction>
            <ode>
              <mu>0.2</mu>
              <mu2>0.2</mu2>
            </ode>
          </friction>
        </surface>
      </collision>
      <visual name='link2_visual'>
        <pose>0 0 0 0 -0 0</pose>
        <geometry>
          <mesh>
            <scale>0.001 0.001 0.001</scale>
            <uri>file:///home/demo/test_ws/src/roarm_description/meshes/roarm_m3/link2.stl</uri>
          </mesh>
        </geometry>
        <material>
          <script>
            <name>Gazebo/Silver</name>
            <uri>file://media/materials/scripts/gazebo.material</uri>
          </script>
        </material>
      </visual>
      <self_collide>0</self_collide>
    </link>
    <joint name='link2_to_link3' type='revolute'>
      <pose relative_to='link2'>0.236815 0.030002 0 0 -0 1.5708</pose>
      <parent>link2</parent>
      <child>link3</child>
      <axis>
        <xyz>0 0 1</xyz>
        <initial_position>1.57</initial_position>
        <limit>
          <lower>-1</lower>
          <upper>2.95</upper>
          <effort>2.6</effort>
          <velocity>2</velocity>
        </limit>
        <dynamics>
          <damping>0.001</damping>
          <friction>0.001</friction>
          <spring_reference>0</spring_reference>
          <spring_stiffness>0</spring_stiffness>
        </dynamics>
      </axis>
    </joint>
    <link name='link3'>
      <pose relative_to='link2_to_link3'>0 0 0 0 -0 0</pose>
      <inertial>
        <pose>-0.0015 -0.0765 0.00505 0 -0 0</pose>
        <mass>0.021608</mass>
        <inertia>
          <ixx>6.37699e-05</ixx>
          <ixy>0</ixy>
          <ixz>0</ixz>
          <iyy>3.67026e-06</iyy>
          <iyz>0</iyz>
          <izz>6.28965e-05</izz>
        </inertia>
      </inertial>
      <collision name='link3_collision'>
        <pose>0 0 0 0 -0 0</pose>
        <geometry>
          <mesh>
            <scale>0.001 0.001 0.001</scale>
            <uri>file:///home/demo/test_ws/src/roarm_description/meshes/roarm_m3/link3.stl</uri>
          </mesh>
        </geometry>
        <surface>
          <contact>
            <ode/>
          </contact>
          <friction>
            <ode>
              <mu>0.03</mu>
              <mu2>0.03</mu2>
            </ode>
          </friction>
        </surface>
      </collision>
      <visual name='link3_visual'>
        <pose>0 0 0 0 -0 0</pose>
        <geometry>
          <mesh>
            <scale>0.001 0.001 0.001</scale>
            <uri>file:///home/demo/test_ws/src/roarm_description/meshes/roarm_m3/link3.stl</uri>
          </mesh>
        </geometry>
        <material>
          <script>
            <name>Gazebo/Silver</name>
            <uri>file://media/materials/scripts/gazebo.material</uri>
          </script>
        </material>
      </visual>
      <self_collide>0</self_collide>
    </link>
    <joint name='link3_to_link4' type='revolute'>
      <pose relative_to='link3'>0 -0.144586 0 0 -0 0</pose>
      <parent>link3</parent>
      <child>link4</child>
      <axis>
        <xyz>0 0 1</xyz>
        <initial_position>0</initial_position>
        <limit>
          <lower>-1.5708</lower>
          <upper>1.5708</upper>
          <effort>1.9</effort>
          <velocity>2.5</velocity>
        </limit>
        <dynamics>
          <damping>0.005</damping>
          <friction>0.005</friction>
          <spring_reference>0</spring_reference>
          <spring_stiffness>0</spring_stiffness>
        </dynamics>
      </axis>
    </joint>
    <link name='link4'>
      <pose relative_to='link3_to_link4'>0 0 0 0 -0 0</pose>
      <inertial>
        <pose>-0.0015 -0.022 -0.00075 0 -0 0</pose>
        <mass>0.0099933</mass>
        <inertia>
          <ixx>4.53979e-06</ixx>
          <ixy>0</ixy>
          <ixz>0</ixz>
          <iyy>3.78103e-06</iyy>
          <iyz>0</iyz>
          <izz>5.60238e-06</izz>
        </inertia>
      </inertial>
      <collision name='link4_collision'>
        <pose>0 0 0 0 -0 0</pose>
        <geometry>
          <mesh>
            <scale>0.001 0.001 0.001</scale>
            <uri>file:///home/demo/test_ws/src/roarm_description/meshes/roarm_m3/link4.stl</uri>
          </mesh>
        </geometry>
        <surface>
          <contact>
            <ode/>
          </contact>
          <friction>
            <ode>
              <mu>0.03</mu>
              <mu2>0.03</mu2>
            </ode>
          </friction>
        </surface>
      </collision>
      <visual name='link4_visual'>
        <pose>0 0 0 0 -0 0</pose>
        <geometry>
          <mesh>
            <scale>0.001 0.001 0.001</scale>
            <uri>file:///home/demo/test_ws/src/roarm_description/meshes/roarm_m3/link4.stl</uri>
          </mesh>
        </geometry>
        <material>
          <script>
            <name>Gazebo/Silver</name>
            <uri>file://media/materials/scripts/gazebo.material</uri>
          </script>
        </material>
      </visual>
      <self_collide>0</self_collide>
    </link>
    <joint name='link4_to_link5' type='revolute'>
      <pose relative_to='link4'>0.015147 -0.053653 0 -1.57079 1.57079 3.14159</pose>
      <parent>link4</parent>
      <child>link5</child>
      <axis>
        <xyz>0 0 1</xyz>
        <initial_position>0</initial_position>
        <limit>
          <lower>-3.1416</lower>
          <upper>3.1416</upper>
          <effort>1.9</effort>
          <velocity>2.5</velocity>
        </limit>
        <dynamics>
          <damping>0.001</damping>
          <friction>0.001</friction>
          <spring_reference>0</spring_reference>
          <spring_stiffness>0</spring_stiffness>
        </dynamics>
      </axis>
    </joint>
    <link name='link5'>
      <pose relative_to='link4_to_link5'>0 0 0 0 -0 0</pose>
      <inertial>
        <pose>-0.0078 0 0.0595 0 -0 0</pose>
        <mass>0.0153928</mass>
        <inertia>
          <ixx>2.02869e-05</ixx>
          <ixy>0</ixy>
          <ixz>0</ixz>
          <iyy>2.14427e-05</iyy>
          <iyz>0</iyz>
          <izz>4.39495e-06</izz>
        </inertia>
      </inertial>
      <collision name='link5_collision'>
        <pose>0 0 0 0 -0 0</pose>
        <geometry>
          <mesh>
            <scale>0.001 0.001 0.001</scale>
            <uri>file:///home/demo/test_ws/src/roarm_description/meshes/roarm_m3/link5.stl</uri>
          </mesh>
        </geometry>
        <surface>
          <contact>
            <ode/>
          </contact>
          <friction>
            <ode>
              <mu>0.03</mu>
              <mu2>0.03</mu2>
            </ode>
          </friction>
        </surface>
      </collision>
      <visual name='link5_visual'>
        <pose>0 0 0 0 -0 0</pose>
        <geometry>
          <mesh>
            <scale>0.001 0.001 0.001</scale>
            <uri>file:///home/demo/test_ws/src/roarm_description/meshes/roarm_m3/link5.stl</uri>
          </mesh>
        </geometry>
        <material>
          <script>
            <name>Gazebo/Silver</name>
            <uri>file://media/materials/scripts/gazebo.material</uri>
          </script>
        </material>
      </visual>
      <self_collide>0</self_collide>
    </link>
    <joint name='link5_to_gripper_link' type='revolute'>
      <pose relative_to='link5'>0 0.018821 0.052035 1.57079 -1.57079 3.14159</pose>
      <parent>link5</parent>
      <child>gripper_link</child>
      <axis>
        <xyz>0 0 1</xyz>
        <initial_position>0</initial_position>
        <limit>
          <lower>0</lower>
          <upper>1.5</upper>
          <effort>1</effort>
          <velocity>2</velocity>
        </limit>
        <dynamics>
          <damping>0.001</damping>
          <friction>0.001</friction>
          <spring_reference>0</spring_reference>
          <spring_stiffness>0</spring_stiffness>
        </dynamics>
      </axis>
    </joint>
    <link name='gripper_link'>
      <pose relative_to='link5_to_gripper_link'>0 0 0 0 -0 0</pose>
      <inertial>
        <pose>0.027 0.0027 -0.018935 0 -0 0</pose>
        <mass>0.0028708</mass>
        <inertia>
          <ixx>5.23216e-07</ixx>
          <ixy>0</ixy>
          <ixz>0</ixz>
          <iyy>1.82071e-06</iyy>
          <iyz>0</iyz>
          <izz>1.60231e-06</izz>
        </inertia>
      </inertial>
      <collision name='gripper_link_collision'>
        <pose>0 0 0 0 -0 0</pose>
        <geometry>
          <mesh>
            <scale>0.001 0.001 0.001</scale>
            <uri>file:///home/demo/test_ws/src/roarm_description/meshes/roarm_m3/gripper_link.stl</uri>
          </mesh>
        </geometry>
        <surface>
          <contact>
            <ode/>
          </contact>
          <friction>
            <ode>
              <mu>0.03</mu>
              <mu2>0.03</mu2>
            </ode>
          </friction>
        </surface>
      </collision>
      <visual name='gripper_link_visual'>
        <pose>0 0 0 0 -0 0</pose>
        <geometry>
          <mesh>
            <scale>0.001 0.001 0.001</scale>
            <uri>file:///home/demo/test_ws/src/roarm_description/meshes/roarm_m3/gripper_link.stl</uri>
          </mesh>
        </geometry>
        <material>
          <script>
            <name>Gazebo/Silver</name>
            <uri>file://media/materials/scripts/gazebo.material</uri>
          </script>
        </material>
      </visual>
      <self_collide>0</self_collide>
    </link>
    <joint name='rotor_1_link_joint' type='revolute'>
      <pose relative_to='base_link'>0.34877 0.20136 0.041041 0 -0 0</pose>
      <parent>base_link</parent>
      <child>rotor_1_link</child>
      <axis>
        <xyz>-0.048924 -0.028246 0.9984</xyz>
        <limit>
          <lower>-1e+16</lower>
          <upper>1e+16</upper>
        </limit>
        <dynamics>
          <spring_reference>0</spring_reference>
          <spring_stiffness>0</spring_stiffness>
        </dynamics>
      </axis>
    </joint>
    <link name='rotor_1_link'>
      <pose relative_to='rotor_1_link_joint'>0 0 0 0 -0 0</pose>
      <inertial>
        <pose>0.000865 0.000496 -0.017044 0 -0 0</pose>
        <mass>0.021154</mass>
        <inertia>
          <ixx>9.7523e-06</ixx>
          <ixy>4.5374e-06</ixy>
          <ixz>-1.105e-07</ixz>
          <iyy>5.1094e-06</iyy>
          <iyz>-4.104e-08</iyz>
          <izz>1.4591e-05</izz>
        </inertia>
      </inertial>
      <collision name='rotor_1_link_collision'>
        <pose>0 0 0 0 -0 0</pose>
        <geometry>
          <mesh>
            <scale>1 1 1</scale>
            <uri>file:///home/demo/test_ws/src/myam_description/meshes/rotor_1_link.STL</uri>
          </mesh>
        </geometry>
      </collision>
      <visual name='rotor_1_link_visual'>
        <pose>0 0 0 0 -0 0</pose>
        <geometry>
          <mesh>
            <scale>1 1 1</scale>
            <uri>file:///home/demo/test_ws/src/myam_description/meshes/rotor_1_link.STL</uri>
          </mesh>
        </geometry>
      </visual>
    </link>
    <joint name='rotor_2_link_joint' type='revolute'>
      <pose relative_to='base_link'>0.3488 -0.20138 0.040896 0 -0 0</pose>
      <parent>base_link</parent>
      <child>rotor_2_link</child>
      <axis>
        <xyz>-0.048454 0.027975 0.99843</xyz>
        <limit>
          <lower>-1e+16</lower>
          <upper>1e+16</upper>
        </limit>
        <dynamics>
          <spring_reference>0</spring_reference>
          <spring_stiffness>0</spring_stiffness>
        </dynamics>
      </axis>
    </joint>
    <link name='rotor_2_link'>
      <pose relative_to='rotor_2_link_joint'>0 0 0 0 -0 0</pose>
      <inertial>
        <pose>0.000921 -0.000539 -0.016732 0 -0 0</pose>
        <mass>0.021907</mass>
        <inertia>
          <ixx>1.2151e-05</ixx>
          <ixy>-6.0793e-06</ixy>
          <ixz>-1.111e-07</ixz>
          <iyy>6.1483e-06</iyy>
          <iyz>3.528e-08</iyz>
          <izz>1.8022e-05</izz>
        </inertia>
      </inertial>
      <collision name='rotor_2_link_collision'>
        <pose>0 0 0 0 -0 0</pose>
        <geometry>
          <mesh>
            <scale>1 1 1</scale>
            <uri>file:///home/demo/test_ws/src/myam_description/meshes/rotor_2_link.STL</uri>
          </mesh>
        </geometry>
      </collision>
      <visual name='rotor_2_link_visual'>
        <pose>0 0 0 0 -0 0</pose>
        <geometry>
          <mesh>
            <scale>1 1 1</scale>
            <uri>file:///home/demo/test_ws/src/myam_description/meshes/rotor_2_link.STL</uri>
          </mesh>
        </geometry>
      </visual>
    </link>
    <joint name='rotor_3_link_joint' type='revolute'>
      <pose relative_to='base_link'>0 -0.40268 0.041175 0 -0 0</pose>
      <parent>base_link</parent>
      <child>rotor_3_link</child>
      <axis>
        <xyz>0 0.056997 0.99837</xyz>
        <limit>
          <lower>-1e+16</lower>
          <upper>1e+16</upper>
        </limit>
        <dynamics>
          <spring_reference>0</spring_reference>
          <spring_stiffness>0</spring_stiffness>
        </dynamics>
      </axis>
    </joint>
    <link name='rotor_3_link'>
      <pose relative_to='rotor_3_link_joint'>0 0 0 0 -0 0</pose>
      <inertial>
        <pose>0.000132 -0.000922 -0.0171 0 -0 0</pose>
        <mass>0.021043</mass>
        <inertia>
          <ixx>2.343e-06</ixx>
          <ixy>-3.5166e-07</ixy>
          <ixz>2.5278e-08</ixz>
          <iyy>1.1905e-05</iyy>
          <iyz>1.2057e-07</iyz>
          <izz>1.3977e-05</izz>
        </inertia>
      </inertial>
      <collision name='rotor_3_link_collision'>
        <pose>0 0 0 0 -0 0</pose>
        <geometry>
          <mesh>
            <scale>1 1 1</scale>
            <uri>file:///home/demo/test_ws/src/myam_description/meshes/rotor_3_link.STL</uri>
          </mesh>
        </geometry>
      </collision>
      <visual name='rotor_3_link_visual'>
        <pose>0 0 0 0 -0 0</pose>
        <geometry>
          <mesh>
            <scale>1 1 1</scale>
            <uri>file:///home/demo/test_ws/src/myam_description/meshes/rotor_3_link.STL</uri>
          </mesh>
        </geometry>
      </visual>
    </link>
    <joint name='rotor_4_link_joint' type='revolute'>
      <pose relative_to='base_link'>-0.34883 -0.2014 0.040769 0 -0 0</pose>
      <parent>base_link</parent>
      <child>rotor_4_link</child>
      <axis>
        <xyz>0.048041 0.027736 0.99846</xyz>
        <limit>
          <lower>-1e+16</lower>
          <upper>1e+16</upper>
        </limit>
        <dynamics>
          <spring_reference>0</spring_reference>
          <spring_stiffness>0</spring_stiffness>
        </dynamics>
      </axis>
    </joint>
    <link name='rotor_4_link'>
      <pose relative_to='rotor_4_link_joint'>0 0 0 0 -0 0</pose>
      <inertial>
        <pose>-0.000958 -0.000546 -0.016731 0 -0 0</pose>
        <mass>0.021907</mass>
        <inertia>
          <ixx>1.2729e-05</ixx>
          <ixy>5.7553e-06</ixy>
          <ixz>8.9654e-08</ixz>
          <iyy>5.57e-06</iyy>
          <iyz>6.6405e-08</iyz>
          <izz>1.8023e-05</izz>
        </inertia>
      </inertial>
      <collision name='rotor_4_link_collision'>
        <pose>0 0 0 0 -0 0</pose>
        <geometry>
          <mesh>
            <scale>1 1 1</scale>
            <uri>file:///home/demo/test_ws/src/myam_description/meshes/rotor_4_link.STL</uri>
          </mesh>
        </geometry>
      </collision>
      <visual name='rotor_4_link_visual'>
        <pose>0 0 0 0 -0 0</pose>
        <geometry>
          <mesh>
            <scale>1 1 1</scale>
            <uri>file:///home/demo/test_ws/src/myam_description/meshes/rotor_4_link.STL</uri>
          </mesh>
        </geometry>
      </visual>
    </link>
    <joint name='rotor_5_link_joint' type='revolute'>
      <pose relative_to='base_link'>-0.34873 0.20134 0.041175 0 -0 0</pose>
      <parent>base_link</parent>
      <child>rotor_5_link</child>
      <axis>
        <xyz>0.049361 -0.028499 0.99837</xyz>
        <limit>
          <lower>-1e+16</lower>
          <upper>1e+16</upper>
        </limit>
        <dynamics>
          <spring_reference>0</spring_reference>
          <spring_stiffness>0</spring_stiffness>
        </dynamics>
      </axis>
    </joint>
    <link name='rotor_5_link'>
      <pose relative_to='rotor_5_link_joint'>0 0 0 0 -0 0</pose>
      <inertial>
        <pose>-0.000787 0.000471 -0.017046 0 -0 0</pose>
        <mass>0.021159</mass>
        <inertia>
          <ixx>1.0284e-05</ixx>
          <ixy>-4.2421e-06</ixy>
          <ixz>9.245e-08</ixz>
          <iyy>4.5973e-06</iyy>
          <iyz>-8.1212e-08</iyz>
          <izz>1.4609e-05</izz>
        </inertia>
      </inertial>
      <collision name='rotor_5_link_collision'>
        <pose>0 0 0 0 -0 0</pose>
        <geometry>
          <mesh>
            <scale>1 1 1</scale>
            <uri>file:///home/demo/test_ws/src/myam_description/meshes/rotor_5_link.STL</uri>
          </mesh>
        </geometry>
      </collision>
      <visual name='rotor_5_link_visual'>
        <pose>0 0 0 0 -0 0</pose>
        <geometry>
          <mesh>
            <scale>1 1 1</scale>
            <uri>file:///home/demo/test_ws/src/myam_description/meshes/rotor_5_link.STL</uri>
          </mesh>
        </geometry>
      </visual>
    </link>
    <joint name='rotor_6_link_joint' type='revolute'>
      <pose relative_to='base_link'>0 0.4028 0.040769 0 -0 0</pose>
      <parent>base_link</parent>
      <child>rotor_6_link</child>
      <axis>
        <xyz>0 -0.055473 0.99846</xyz>
        <limit>
          <lower>-1e+16</lower>
          <upper>1e+16</upper>
        </limit>
        <dynamics>
          <spring_reference>0</spring_reference>
          <spring_stiffness>0</spring_stiffness>
        </dynamics>
      </axis>
    </joint>
    <link name='rotor_6_link'>
      <pose relative_to='rotor_6_link_joint'>0 0 0 0 -0 0</pose>
      <inertial>
        <pose>4e-06 0.001103 -0.01673 0 -0 0</pose>
        <mass>0.021907</mass>
        <inertia>
          <ixx>2.3754e-06</ixx>
          <ixy>2.222e-07</ixy>
          <ixz>1.2652e-08</ixz>
          <iyy>1.5929e-05</iyy>
          <iyz>-1.1083e-07</iyz>
          <izz>1.8028e-05</izz>
        </inertia>
      </inertial>
      <collision name='rotor_6_link_collision'>
        <pose>0 0 0 0 -0 0</pose>
        <geometry>
          <mesh>
            <scale>1 1 1</scale>
            <uri>file:///home/demo/test_ws/src/myam_description/meshes/rotor_6_link.STL</uri>
          </mesh>
        </geometry>
      </collision>
      <visual name='rotor_6_link_visual'>
        <pose>0 0 0 0 -0 0</pose>
        <geometry>
          <mesh>
            <scale>1 1 1</scale>
            <uri>file:///home/demo/test_ws/src/myam_description/meshes/rotor_6_link.STL</uri>
          </mesh>
        </geometry>
      </visual>
    </link>
    <plugin name='camera_realsense' filename='librealsense_gazebo_plugin.so'>
      <prefix>camera_</prefix>
      <depthUpdateRate>20</depthUpdateRate>
      <colorUpdateRate>20</colorUpdateRate>
      <infraredUpdateRate>5</infraredUpdateRate>
      <depthTopicName>depth/image_raw</depthTopicName>
      <depthCameraInfoTopicName>depth/camera_info</depthCameraInfoTopicName>
      <colorTopicName>color/image_raw</colorTopicName>
      <colorCameraInfoTopicName>color/camera_info</colorCameraInfoTopicName>
      <infrared1TopicName>infra1/image_raw</infrared1TopicName>
      <infrared1CameraInfoTopicName>infra1/camera_info</infrared1CameraInfoTopicName>
      <infrared2TopicName>infra2/image_raw</infrared2TopicName>
      <infrared2CameraInfoTopicName>infra2/camera_info</infrared2CameraInfoTopicName>
      <colorOpticalframeName>camera_color_optical_frame</colorOpticalframeName>
      <depthOpticalframeName>camera_depth_optical_frame</depthOpticalframeName>
      <infrared1OpticalframeName>camera_left_ir_optical_frame</infrared1OpticalframeName>
      <infrared2OpticalframeName>camera_right_ir_optical_frame</infrared2OpticalframeName>
      <rangeMinDepth>0.2</rangeMinDepth>
      <rangeMaxDepth>10.0</rangeMaxDepth>
      <pointCloud>0</pointCloud>
      <pointCloudTopicName>depth/color/points</pointCloudTopicName>
      <pointCloudCutoff>0.25</pointCloudCutoff>
      <pointCloudCutoffMax>9.0</pointCloudCutoffMax>
    </plugin>
    <plugin name='gazebo_ros_control' filename='libgazebo_ros_control.so'>
      <robotNamespace>/</robotNamespace>
      <robotParam>/myam_arm_description</robotParam>
    </plugin>

    <plugin name='multirotor_base' filename='libgazebo_multirotor_base_plugin.so'>
      <robotNamespace/>
      <linkName>base_link</linkName>
      <rotorVelocitySlowdownSim>10</rotorVelocitySlowdownSim>
    </plugin>
    <plugin name='motor_0' filename='libgazebo_motor_model.so'><robotNamespace/><jointName>rotor_1_link_joint</jointName><linkName>rotor_1_link</linkName><turningDirection>ccw</turningDirection><timeConstantUp>0.0125</timeConstantUp><timeConstantDown>0.025</timeConstantDown><maxRotVelocity>1500</maxRotVelocity><motorConstant>8.54858e-06</motorConstant><momentConstant>0.06</momentConstant><commandSubTopic>/gazebo/command/motor_speed</commandSubTopic><motorNumber>0</motorNumber><rotorDragCoefficient>0.000806428</rotorDragCoefficient><rollingMomentCoefficient>1e-06</rollingMomentCoefficient><motorSpeedPubTopic>/motor_speed/0</motorSpeedPubTopic><rotorVelocitySlowdownSim>10</rotorVelocitySlowdownSim></plugin>
    <plugin name='motor_1' filename='libgazebo_motor_model.so'><robotNamespace/><jointName>rotor_2_link_joint</jointName><linkName>rotor_2_link</linkName><turningDirection>cw</turningDirection><timeConstantUp>0.0125</timeConstantUp><timeConstantDown>0.025</timeConstantDown><maxRotVelocity>1500</maxRotVelocity><motorConstant>8.54858e-06</motorConstant><momentConstant>0.06</momentConstant><commandSubTopic>/gazebo/command/motor_speed</commandSubTopic><motorNumber>1</motorNumber><rotorDragCoefficient>0.000806428</rotorDragCoefficient><rollingMomentCoefficient>1e-06</rollingMomentCoefficient><motorSpeedPubTopic>/motor_speed/1</motorSpeedPubTopic><rotorVelocitySlowdownSim>10</rotorVelocitySlowdownSim></plugin>
    <plugin name='motor_2' filename='libgazebo_motor_model.so'><robotNamespace/><jointName>rotor_3_link_joint</jointName><linkName>rotor_3_link</linkName><turningDirection>ccw</turningDirection><timeConstantUp>0.0125</timeConstantUp><timeConstantDown>0.025</timeConstantDown><maxRotVelocity>1500</maxRotVelocity><motorConstant>8.54858e-06</motorConstant><momentConstant>0.06</momentConstant><commandSubTopic>/gazebo/command/motor_speed</commandSubTopic><motorNumber>2</motorNumber><rotorDragCoefficient>0.000806428</rotorDragCoefficient><rollingMomentCoefficient>1e-06</rollingMomentCoefficient><motorSpeedPubTopic>/motor_speed/2</motorSpeedPubTopic><rotorVelocitySlowdownSim>10</rotorVelocitySlowdownSim></plugin>
    <plugin name='motor_3' filename='libgazebo_motor_model.so'><robotNamespace/><jointName>rotor_4_link_joint</jointName><linkName>rotor_4_link</linkName><turningDirection>cw</turningDirection><timeConstantUp>0.0125</timeConstantUp><timeConstantDown>0.025</timeConstantDown><maxRotVelocity>1500</maxRotVelocity><motorConstant>8.54858e-06</motorConstant><momentConstant>0.06</momentConstant><commandSubTopic>/gazebo/command/motor_speed</commandSubTopic><motorNumber>3</motorNumber><rotorDragCoefficient>0.000806428</rotorDragCoefficient><rollingMomentCoefficient>1e-06</rollingMomentCoefficient><motorSpeedPubTopic>/motor_speed/3</motorSpeedPubTopic><rotorVelocitySlowdownSim>10</rotorVelocitySlowdownSim></plugin>
    <plugin name='motor_4' filename='libgazebo_motor_model.so'><robotNamespace/><jointName>rotor_5_link_joint</jointName><linkName>rotor_5_link</linkName><turningDirection>ccw</turningDirection><timeConstantUp>0.0125</timeConstantUp><timeConstantDown>0.025</timeConstantDown><maxRotVelocity>1500</maxRotVelocity><motorConstant>8.54858e-06</motorConstant><momentConstant>0.06</momentConstant><commandSubTopic>/gazebo/command/motor_speed</commandSubTopic><motorNumber>4</motorNumber><rotorDragCoefficient>0.000806428</rotorDragCoefficient><rollingMomentCoefficient>1e-06</rollingMomentCoefficient><motorSpeedPubTopic>/motor_speed/4</motorSpeedPubTopic><rotorVelocitySlowdownSim>10</rotorVelocitySlowdownSim></plugin>
    <plugin name='motor_5' filename='libgazebo_motor_model.so'><robotNamespace/><jointName>rotor_6_link_joint</jointName><linkName>rotor_6_link</linkName><turningDirection>cw</turningDirection><timeConstantUp>0.0125</timeConstantUp><timeConstantDown>0.025</timeConstantDown><maxRotVelocity>1500</maxRotVelocity><motorConstant>8.54858e-06</motorConstant><momentConstant>0.06</momentConstant><commandSubTopic>/gazebo/command/motor_speed</commandSubTopic><motorNumber>5</motorNumber><rotorDragCoefficient>0.000806428</rotorDragCoefficient><rollingMomentCoefficient>1e-06</rollingMomentCoefficient><motorSpeedPubTopic>/motor_speed/5</motorSpeedPubTopic><rotorVelocitySlowdownSim>10</rotorVelocitySlowdownSim></plugin>
    <include><uri>model://gps</uri><pose>0.05 0 0.04 0 0 0</pose><name>gps0</name></include>
    <joint name='gps0_joint' type='fixed'><child>gps0::link</child><parent>base_link</parent></joint>
    <plugin name='groundtruth_plugin' filename='libgazebo_groundtruth_plugin.so'><robotNamespace/></plugin>
    <plugin name='magnetometer_plugin' filename='libgazebo_magnetometer_plugin.so'><robotNamespace/><magTopic>/mag</magTopic><magNoise>0.000004</magNoise></plugin>
    <plugin name='barometer_plugin' filename='libgazebo_barometer_plugin.so'><robotNamespace/><pubRate>50</pubRate><baroTopic>/baro</baroTopic></plugin>
    <plugin name='mavlink_interface' filename='libgazebo_mavlink_interface.so'><robotNamespace/><imuSubTopic>/imu</imuSubTopic><magSubTopic>/mag</magSubTopic><baroSubTopic>/baro</baroSubTopic><mavlink_addr>INADDR_ANY</mavlink_addr><mavlink_tcp_port>4560</mavlink_tcp_port><mavlink_udp_port>14560</mavlink_udp_port><serialEnabled>0</serialEnabled><qgc_addr>INADDR_ANY</qgc_addr><qgc_udp_port>14550</qgc_udp_port><sdk_addr>INADDR_ANY</sdk_addr><sdk_udp_port>14540</sdk_udp_port><hil_mode>0</hil_mode><hil_state_level>false</hil_state_level>
      <enable_lockstep>false</enable_lockstep><use_tcp>true</use_tcp><motorSpeedCommandPubTopic>/gazebo/command/motor_speed</motorSpeedCommandPubTopic><control_channels><channel name='rotor0'><input_index>0</input_index><input_offset>0</input_offset><input_scaling>1500</input_scaling><zero_position_disarmed>0</zero_position_disarmed><zero_position_armed>100</zero_position_armed><joint_control_type>velocity</joint_control_type></channel><channel name='rotor1'><input_index>1</input_index><input_offset>0</input_offset><input_scaling>1500</input_scaling><zero_position_disarmed>0</zero_position_disarmed><zero_position_armed>100</zero_position_armed><joint_control_type>velocity</joint_control_type></channel><channel name='rotor2'><input_index>2</input_index><input_offset>0</input_offset><input_scaling>1500</input_scaling><zero_position_disarmed>0</zero_position_disarmed><zero_position_armed>100</zero_position_armed><joint_control_type>velocity</joint_control_type></channel><channel name='rotor3'><input_index>3</input_index><input_offset>0</input_offset><input_scaling>1500</input_scaling><zero_position_disarmed>0</zero_position_disarmed><zero_position_armed>100</zero_position_armed><joint_control_type>velocity</joint_control_type></channel><channel name='rotor4'><input_index>4</input_index><input_offset>0</input_offset><input_scaling>1500</input_scaling><zero_position_disarmed>0</zero_position_disarmed><zero_position_armed>100</zero_position_armed><joint_control_type>velocity</joint_control_type></channel><channel name='rotor5'><input_index>5</input_index><input_offset>0</input_offset><input_scaling>1500</input_scaling><zero_position_disarmed>0</zero_position_disarmed><zero_position_armed>100</zero_position_armed><joint_control_type>velocity</joint_control_type></channel></control_channels></plugin>
    <static>0</static>
    <plugin name='gazebo_imu_plugin' filename='libgazebo_imu_plugin.so'><robotNamespace/><linkName>base_link</linkName><imuTopic>/imu</imuTopic><gyroscopeNoiseDensity>0.0003394</gyroscopeNoiseDensity><gyroscopeRandomWalk>3.8785e-05</gyroscopeRandomWalk><gyroscopeBiasCorrelationTime>1000.0</gyroscopeBiasCorrelationTime><gyroscopeTurnOnBiasSigma>0.0087</gyroscopeTurnOnBiasSigma><accelerometerNoiseDensity>0.004</accelerometerNoiseDensity><accelerometerRandomWalk>0.00004</accelerometerRandomWalk><accelerometerBiasCorrelationTime>300.0</accelerometerBiasCorrelationTime><accelerometerTurnOnBiasSigma>0.196</accelerometerTurnOnBiasSigma></plugin>
    <frame name='arm_mount_joint' attached_to='base_link'>
      <pose>0.073168 -0.002113 -0.2185 3.14159 -0 0.000221</pose>
    </frame>
    <frame name='roarm_base_link' attached_to='arm_mount_joint'/>
    <frame name='link5_to_hand_tcp' attached_to='link5'>
      <pose>0 0 0.115428 -1.57079 -1.57079 3.14159</pose>
    </frame>
    <frame name='hand_tcp' attached_to='link5_to_hand_tcp'/>
    <frame name='battery_joint' attached_to='base_link'>
      <pose>-0.061817 -2.3e-05 -0.068921 0 -0 0</pose>
    </frame>
    <frame name='battery_link' attached_to='battery_joint'/>
    <frame name='camera_color_optical_joint' attached_to='camera_color_frame'>
      <pose>0 0 0 -1.5708 -0 -1.5708</pose>
    </frame>
    <frame name='camera_color_optical_frame' attached_to='camera_color_optical_joint'/>
    <frame name='camera_color_joint' attached_to='camera_depth_frame'>
      <pose>0 0.015 0 0 -0 0</pose>
    </frame>
    <frame name='camera_color_frame' attached_to='camera_color_joint'/>
    <frame name='camera_depth_optical_joint' attached_to='camera_depth_frame'>
      <pose>0 0 0 -1.5708 -0 -1.5708</pose>
    </frame>
    <frame name='camera_depth_optical_frame' attached_to='camera_depth_optical_joint'/>
    <frame name='camera_left_ir_optical_joint' attached_to='camera_left_ir_frame'>
      <pose>0 0 0 -1.5708 -0 -1.5708</pose>
    </frame>
    <frame name='camera_left_ir_optical_frame' attached_to='camera_left_ir_optical_joint'/>
    <frame name='camera_left_ir_joint' attached_to='camera_depth_frame'>
      <pose>0 0 0 0 -0 0</pose>
    </frame>
    <frame name='camera_left_ir_frame' attached_to='camera_left_ir_joint'/>
    <frame name='camera_right_ir_optical_joint' attached_to='camera_right_ir_frame'>
      <pose>0 0 0 -1.5708 -0 -1.5708</pose>
    </frame>
    <frame name='camera_right_ir_optical_frame' attached_to='camera_right_ir_optical_joint'/>
    <frame name='camera_right_ir_joint' attached_to='camera_depth_frame'>
      <pose>0 -0.05 0 0 -0 0</pose>
    </frame>
    <frame name='camera_right_ir_frame' attached_to='camera_right_ir_joint'/>
    <frame name='camera_depth_joint' attached_to='camera_link'>
      <pose>0 0 0 0 -0 0</pose>
    </frame>
    <frame name='camera_depth_frame' attached_to='camera_depth_joint'/>
    <frame name='camera_link_joint' attached_to='camera_bottom_screw_frame'>
      <pose>0 0.0175 0.0125 0 -0 0</pose>
    </frame>
    <frame name='camera_link' attached_to='camera_link_joint'/>
    <frame name='camera_joint' attached_to='base_link'>
      <pose>0.155 -0.005 -0.158 3.14159 1.57079 3.14159</pose>
    </frame>
    <frame name='camera_bottom_screw_frame' attached_to='camera_joint'/>
    <frame name='gps_joint' attached_to='base_link'>
      <pose>-0.000407 1.3e-05 0.17697 0 -0 0</pose>
    </frame>
    <frame name='gps_link' attached_to='gps_joint'/>
    <frame name='imu_joint' attached_to='base_link'>
      <pose>-0.095599 4.1e-05 -0.013807 0 -0 0</pose>
    </frame>
    <frame name='imu_link' attached_to='imu_joint'/>
    <frame name='landing_gear_1_joint' attached_to='base_link'>
      <pose>-1.3e-05 0.21064 -0.40283 0 -0 0</pose>
    </frame>
    <frame name='landing_gear_1_link' attached_to='landing_gear_1_joint'/>
    <frame name='landing_gear_2_joint' attached_to='base_link'>
      <pose>-1.3e-05 -0.21064 -0.40283 0 -0 0</pose>
    </frame>
    <frame name='landing_gear_2_link' attached_to='landing_gear_2_joint'/>
</model>
</sdf>
