<?xml version="1.0" ?>
<!-- =================================================================================== -->
<!-- |    This document was autogenerated by xacro from /home/demo/test_ws/src/roarm_description/urdf/roarm_m3/roarm_m3.xacro | -->
<!-- |    EDITING THIS FILE BY HAND IS NOT RECOMMENDED                                 | -->
<!-- =================================================================================== -->
<robot name="roarm_m3">
    <material name="silver">
        <color rgba="0.700 0.700 0.700 1.000" />
    </material>
    <transmission name="base_link_to_link1_tran">
        <type>transmission_interface/SimpleTransmission</type>
        <joint name="base_link_to_link1">
            <hardwareInterface>hardware_interface/EffortJointInterface</hardwareInterface>
        </joint>
        <actuator name="base_link_to_link1_actr">
            <hardwareInterface>hardware_interface/EffortJointInterface</hardwareInterface>
            <mechanicalReduction>1</mechanicalReduction>
        </actuator>
    </transmission>
    <transmission name="link1_to_link2_tran">
        <type>transmission_interface/SimpleTransmission</type>
        <joint name="link1_to_link2">
            <hardwareInterface>hardware_interface/EffortJointInterface</hardwareInterface>
        </joint>
        <actuator name="link1_to_link2_actr">
            <hardwareInterface>hardware_interface/EffortJointInterface</hardwareInterface>
            <mechanicalReduction>1</mechanicalReduction>
        </actuator>
    </transmission>
    <transmission name="link2_to_link3_tran">
        <type>transmission_interface/SimpleTransmission</type>
        <joint name="link2_to_link3">
            <hardwareInterface>hardware_interface/EffortJointInterface</hardwareInterface>
        </joint>
        <actuator name="link2_to_link3_actr">
            <hardwareInterface>hardware_interface/EffortJointInterface</hardwareInterface>
            <mechanicalReduction>1</mechanicalReduction>
        </actuator>
    </transmission>
    <transmission name="link3_to_link4_tran">
        <type>transmission_interface/SimpleTransmission</type>
        <joint name="link3_to_link4">
            <hardwareInterface>hardware_interface/EffortJointInterface</hardwareInterface>
        </joint>
        <actuator name="link3_to_link4_actr">
            <hardwareInterface>hardware_interface/EffortJointInterface</hardwareInterface>
            <mechanicalReduction>1</mechanicalReduction>
        </actuator>
    </transmission>
    <transmission name="link4_to_link5_tran">
        <type>transmission_interface/SimpleTransmission</type>
        <joint name="link4_to_link5">
            <hardwareInterface>hardware_interface/EffortJointInterface</hardwareInterface>
        </joint>
        <actuator name="link4_to_link5_actr">
            <hardwareInterface>hardware_interface/EffortJointInterface</hardwareInterface>
            <mechanicalReduction>1</mechanicalReduction>
        </actuator>
    </transmission>
    <transmission name="link5_to_gripper_link_tran">
        <type>transmission_interface/SimpleTransmission</type>
        <joint name="link5_to_gripper_link">
            <hardwareInterface>hardware_interface/EffortJointInterface</hardwareInterface>
        </joint>
        <actuator name="link5_to_gripper_link_actr">
            <hardwareInterface>hardware_interface/EffortJointInterface</hardwareInterface>
            <mechanicalReduction>1</mechanicalReduction>
        </actuator>
    </transmission>
    <!-- link5_to_hand_tcp 为 fixed 关节：Gazebo 中不暴露为独立关节，勿加 transmission -->
    <gazebo>
        <plugin filename="libgazebo_ros_control.so" name="control" />
        <plugin name="gazebo_ros_control" filename="libgazebo_ros_control.so">
            <robotNamespace>/</robotNamespace>
        </plugin>
    </gazebo>
    <!-- 串联臂相邻 link 若 self_collide=true，网格在关节处易穿透/互挤，与关节约束冲突，解暂停时常“炸开”。同模型内连杆间碰撞应关闭。 -->
    <gazebo reference="base_link">
        <material>Gazebo/Silver</material>
        <mu1>0.2</mu1>
        <mu2>0.2</mu2>
        <self_collide>false</self_collide>
        <gravity>true</gravity>
    </gazebo>
    <gazebo reference="link1">
        <material>Gazebo/Silver</material>
        <mu1>0.2</mu1>
        <mu2>0.2</mu2>
        <self_collide>false</self_collide>
    </gazebo>
    <gazebo reference="link2">
        <material>Gazebo/Silver</material>
        <mu1>0.2</mu1>
        <mu2>0.2</mu2>
        <self_collide>false</self_collide>
    </gazebo>
    <gazebo reference="link3">
        <material>Gazebo/Silver</material>
        <mu1>0.2</mu1>
        <mu2>0.2</mu2>
        <self_collide>false</self_collide>
    </gazebo>
    <gazebo reference="link4">
        <material>Gazebo/Silver</material>
        <mu1>0.2</mu1>
        <mu2>0.2</mu2>
        <self_collide>false</self_collide>
    </gazebo>
    <gazebo reference="link5">
        <material>Gazebo/Silver</material>
        <mu1>0.2</mu1>
        <mu2>0.2</mu2>
        <self_collide>false</self_collide>
    </gazebo>
    <gazebo reference="gripper_link">
        <material>Gazebo/Silver</material>
        <mu1>0.2</mu1>
        <mu2>0.2</mu2>
        <self_collide>false</self_collide>
    </gazebo>
    <link name="world" />
    <link name="base_link">
        <inertial>
            <origin rpy="0 0 0" xyz="-0.0068 0 -0.03" />
            <mass value="0.2562183" />
            <inertia ixx="0.00029211" ixy="0" ixz="0" iyy="0.00035719" iyz="0" izz="0.000349421" />
        </inertial>
        <visual>
            <origin rpy="0 0 0" xyz="0 0 0" />
            <geometry>
                <mesh filename="file:///home/demo/catkin_ws/src/roarm_description/meshes/roarm_m3/base_link.stl" scale="0.001 0.001 0.001" />
            </geometry>
            <material name="silver" />
        </visual>
        <collision>
            <origin rpy="0 0 0" xyz="0 0 0" />
            <geometry>
                <mesh filename="file:///home/demo/catkin_ws/src/roarm_description/meshes/roarm_m3/base_link.stl" scale="0.001 0.001 0.001" />
            </geometry>
        </collision>
    </link>
    <link name="link1">
        <inertial>
            <origin rpy="0 0 0" xyz="0 0 0.037" />
            <mass value="0.0729177" />
            <inertia ixx="4.68465E-05" ixy="0" ixz="0" iyy="3.32107E-05" iyz="0" izz="5.01023E-05" />
        </inertial>
        <visual>
            <origin rpy="0 0 0" xyz="-0.0 -0.0 -0.0" />
            <geometry>
                <mesh filename="file:///home/demo/catkin_ws/src/roarm_description/meshes/roarm_m3/link1.stl" scale="0.001 0.001 0.001" />
            </geometry>
            <material name="silver" />
        </visual>
        <collision>
            <origin rpy="0 0 0" xyz="-0.0 -0.0 -0.0" />
            <geometry>
                <mesh filename="file:///home/demo/catkin_ws/src/roarm_description/meshes/roarm_m3/link1.stl" scale="0.001 0.001 0.001" />
            </geometry>
        </collision>
    </link>
    <link name="link2">
        <inertial>
            <origin rpy="0 0 0" xyz="0.119 0.012247 -0.0001 " />
            <mass value="0.0703216" />
            <inertia ixx="5.46501E-05" ixy="0" ixz="0" iyy="0.000423091" iyz="0" izz="0.000404557" />
        </inertial>
        <visual>
            <origin rpy="0 0 0" xyz="0 0 0" />
            <geometry>
                <mesh filename="file:///home/demo/catkin_ws/src/roarm_description/meshes/roarm_m3/link2.stl" scale="0.001 0.001 0.001" />
            </geometry>
            <material name="silver" />
        </visual>
        <collision>
            <origin rpy="0 0 0" xyz="0 0 0" />
            <geometry>
                <mesh filename="file:///home/demo/catkin_ws/src/roarm_description/meshes/roarm_m3/link2.stl" scale="0.001 0.001 0.001" />
            </geometry>
        </collision>
    </link>
    <link name="link3">
        <inertial>
            <origin rpy="0 0 0" xyz="-0.0015 -0.0765 0.00505" />
            <mass value="0.021608" />
            <inertia ixx="6.37699E-05" ixy="0.0" ixz="0" iyy="3.67026E-06" iyz="0" izz="6.28965E-05" />
        </inertial>
        <visual>
            <origin rpy="0 0 0" xyz="0 0 0" />
            <geometry>
                <mesh filename="file:///home/demo/catkin_ws/src/roarm_description/meshes/roarm_m3/link3.stl" scale="0.001 0.001 0.001" />
            </geometry>
            <material name="silver" />
        </visual>
        <collision>
            <origin rpy="0 0 0" xyz="0 0 0" />
            <geometry>
                <mesh filename="file:///home/demo/catkin_ws/src/roarm_description/meshes/roarm_m3/link3.stl" scale="0.001 0.001 0.001" />
            </geometry>
        </collision>
    </link>
    <link name="link4">
        <inertial>
            <origin rpy="0 0 0" xyz="-0.0015 -0.022 -0.00075" />
            <mass value="0.0099933" />
            <inertia ixx="4.53979E-06" ixy="-0.0" ixz="0.0" iyy="3.78103E-06" iyz="-0.0" izz="5.60238E-06" />
        </inertial>
        <visual>
            <origin rpy="0 0 0" xyz="0 0 0" />
            <geometry>
                <mesh filename="file:///home/demo/catkin_ws/src/roarm_description/meshes/roarm_m3/link4.stl" scale="0.001 0.001 0.001" />
            </geometry>
            <material name="silver" />
        </visual>
        <collision>
            <origin rpy="0 0 0" xyz="0 0 0" />
            <geometry>
                <mesh filename="file:///home/demo/catkin_ws/src/roarm_description/meshes/roarm_m3/link4.stl" scale="0.001 0.001 0.001" />
            </geometry>
        </collision>
    </link>
    <link name="link5">
        <inertial>
            <origin rpy="0 0 0" xyz="-0.0078 0 0.0595" />
            <mass value="0.0153928" />
            <inertia ixx="2.02869E-05" ixy="-0.0" ixz="0" iyy="2.14427E-05" iyz="0" izz="4.39495E-06" />
        </inertial>
        <visual>
            <origin rpy="0 0 0" xyz="0 0 0" />
            <geometry>
                <mesh filename="file:///home/demo/catkin_ws/src/roarm_description/meshes/roarm_m3/link5.stl" scale="0.001 0.001 0.001" />
            </geometry>
            <material name="silver" />
        </visual>
        <collision>
            <origin rpy="0 0 0" xyz="0 0 0" />
            <geometry>
                <mesh filename="file:///home/demo/catkin_ws/src/roarm_description/meshes/roarm_m3/link5.stl" scale="0.001 0.001 0.001" />
            </geometry>
        </collision>
    </link>
    <link name="gripper_link">
        <inertial>
            <origin rpy="0 0 0" xyz="0.027 0.0027 -0.018935" />
            <mass value="0.0028708" />
            <inertia ixx="5.23216E-07" ixy="0" ixz="0" iyy="1.82071E-06" iyz="0" izz="1.60231E-06" />
        </inertial>
        <visual>
            <origin rpy="0 0 0" xyz="0 0 0" />
            <geometry>
                <mesh filename="file:///home/demo/catkin_ws/src/roarm_description/meshes/roarm_m3/gripper_link.stl" scale="0.001 0.001 0.001" />
            </geometry>
            <material name="silver" />
        </visual>
        <collision>
            <origin rpy="0 0 0" xyz="0 0 0" />
            <geometry>
                <mesh filename="file:///home/demo/catkin_ws/src/roarm_description/meshes/roarm_m3/gripper_link.stl" scale="0.001 0.001 0.001" />
            </geometry>
        </collision>
    </link>
    <link name="hand_tcp" />
    <joint name="world_to_base_link" type="fixed">
        <origin rpy="0 0 0" xyz="0.0 0.0 0.0701" />
        <parent link="world" />
        <child link="base_link" />
        <axis xyz="0.0 0.0 1.0" />
    </joint>
    <joint name="base_link_to_link1" type="revolute">
        <origin rpy="0 0 0" xyz="0.0 0.0 0.0" />
        <parent link="base_link" />
        <child link="link1" />
        <axis xyz="0.0 0.0 1.0" />
        <limit effort="2.8" lower="-3.1416" upper="3.1416" velocity="2.2" />
    </joint>
    <joint name="link1_to_link2" type="revolute">
        <origin rpy="-1.5708 -1.5708 0" xyz="0.0 0.0 0.051959" />
        <parent link="link1" />
        <child link="link2" />
        <axis xyz="-0.0 0 1.0" />
        <limit effort="2.8" lower="-1.5708" upper="1.5708" velocity="2" />
    </joint>
    <joint name="link2_to_link3" type="revolute">
        <origin rpy="0 0 1.5708" xyz="0.236815 0.030002 0" />
        <parent link="link2" />
        <child link="link3" />
        <axis xyz="0.0 0.0 1.0" />
        <limit effort="2.6" lower="-1" upper="2.95" velocity="2" />
    </joint>
    <joint name="link3_to_link4" type="revolute">
        <origin rpy="0 0 0" xyz="0.0 -0.144586 0" />
        <parent link="link3" />
        <child link="link4" />
        <axis xyz="0.0 0.0 1.0" />
        <limit effort="1.9" lower="-1.5708" upper="1.5708" velocity="2.5" />
    </joint>
    <joint name="link4_to_link5" type="revolute">
        <origin rpy="1.5708 1.5708 0" xyz="0.015147 -0.053653 0" />
        <parent link="link4" />
        <child link="link5" />
        <axis xyz="0.0 0.0 1.0" />
        <limit effort="1.9" lower="-3.1416" upper="3.1416" velocity="2.5" />
    </joint>
    <joint name="link5_to_gripper_link" type="revolute">
        <origin rpy="-1.5708 -1.5708 0" xyz="0.00 0.018821 0.052035" />
        <parent link="link5" />
        <child link="gripper_link" />
        <axis xyz="0.0 -0.0 1.0" />
        <limit effort="1" lower="0" upper="1.5" velocity="2" />
    </joint>
    <joint name="link5_to_hand_tcp" type="fixed">
        <origin rpy="1.5708 -1.5708 0" xyz="0 0 0.115428" />
        <parent link="link5" />
        <child link="hand_tcp" />
    </joint>
</robot>

