<?xml version="1.0"?>
<robot xmlns:xacro="http://www.ros.org/wiki/xacro">
<xacro:macro name="myam_drone_body">
  <link name="virtual_base"/>

  <joint name="virtual_joint" type="fixed">
    <parent link="virtual_base" />
    <child link="base_link" />
    <origin xyz="0 0 0" rpy="0 0 0" />
  </joint>
  
  <link
    name="base_link">
    <inertial>
      <origin
        xyz="0.0019275 0.0022194 -0.052321"
        rpy="0 0 0" />
      <mass
        value="0.89607" />
      <inertia
        ixx="0.0016514"
        ixy="1.4573E-06"
        ixz="-2.3256E-07"
        iyy="0.0017986"
        iyz="-2.7292E-07"
        izz="0.003277" />
    </inertial>
    <visual>
      <origin
        xyz="0 0 0"
        rpy="0 0 0" />
      <geometry>
        <mesh
          filename="package://myam_description/meshes/base_link.STL" />
      </geometry>
      <material
        name="">
        <color
          rgba="1 1 1 1" />
      </material>
    </visual>
    <collision>
      <origin
        xyz="0 0 0"
        rpy="0 0 0" />
      <geometry>
        <mesh
          filename="package://myam_description/meshes/base_link.STL" />
      </geometry>
    </collision>
  </link>
  <link
    name="rotor_1_link">
    <inertial>
      <origin
        xyz="0.00086471 0.00049638 -0.017044"
        rpy="0 0 0" />
      <mass
        value="0.021154" />
      <inertia
        ixx="9.7523E-06"
        ixy="4.5374E-06"
        ixz="-1.105E-07"
        iyy="5.1094E-06"
        iyz="-4.104E-08"
        izz="1.4591E-05" />
    </inertial>
    <visual>
      <origin
        xyz="0 0 0"
        rpy="0 0 0" />
      <geometry>
        <mesh
          filename="package://myam_description/meshes/rotor_1_link.STL" />
      </geometry>
      <material
        name="">
        <color
          rgba="0.52941 0.54902 0.54902 1" />
      </material>
    </visual>
    <collision>
      <origin
        xyz="0 0 0"
        rpy="0 0 0" />
      <geometry>
        <mesh
          filename="package://myam_description/meshes/rotor_1_link.STL" />
      </geometry>
    </collision>
  </link>
  <joint
    name="rotor_1_joint"
    type="continuous">
    <origin
      xyz="0.34877 0.20136 0.041041"
      rpy="0 0 0" />
    <parent
      link="base_link" />
    <child
      link="rotor_1_link" />
    <axis
      xyz="-0.048924 -0.028246 0.9984" />
  </joint>
  <link
    name="rotor_2_link">
    <inertial>
      <origin
        xyz="0.000921 -0.0005394 -0.016732"
        rpy="0 0 0" />
      <mass
        value="0.021907" />
      <inertia
        ixx="1.2151E-05"
        ixy="-6.0793E-06"
        ixz="-1.111E-07"
        iyy="6.1483E-06"
        iyz="3.528E-08"
        izz="1.8022E-05" />
    </inertial>
    <visual>
      <origin
        xyz="0 0 0"
        rpy="0 0 0" />
      <geometry>
        <mesh
          filename="package://myam_description/meshes/rotor_2_link.STL" />
      </geometry>
      <material
        name="">
        <color
          rgba="1 1 1 1" />
      </material>
    </visual>
    <collision>
      <origin
        xyz="0 0 0"
        rpy="0 0 0" />
      <geometry>
        <mesh
          filename="package://myam_description/meshes/rotor_2_link.STL" />
      </geometry>
    </collision>
  </link>
  <joint
    name="rotor_2_joint"
    type="continuous">
    <origin
      xyz="0.3488 -0.20138 0.040896"
      rpy="0 0 0" />
    <parent
      link="base_link" />
    <child
      link="rotor_2_link" />
    <axis
      xyz="-0.048454 0.027975 0.99843" />
  </joint>
  <link
    name="rotor_3_link">
    <inertial>
      <origin
        xyz="0.00013242 -0.00092207 -0.0171"
        rpy="0 0 0" />
      <mass
        value="0.021043" />
      <inertia
        ixx="2.343E-06"
        ixy="-3.5166E-07"
        ixz="2.5278E-08"
        iyy="1.1905E-05"
        iyz="1.2057E-07"
        izz="1.3977E-05" />
    </inertial>
    <visual>
      <origin
        xyz="0 0 0"
        rpy="0 0 0" />
      <geometry>
        <mesh
          filename="package://myam_description/meshes/rotor_3_link.STL" />
      </geometry>
      <material
        name="">
        <color
          rgba="0.52941 0.54902 0.54902 1" />
      </material>
    </visual>
    <collision>
      <origin
        xyz="0 0 0"
        rpy="0 0 0" />
      <geometry>
        <mesh
          filename="package://myam_description/meshes/rotor_3_link.STL" />
      </geometry>
    </collision>
  </link>
  <joint
    name="rotor_3_joint"
    type="continuous">
    <origin
      xyz="0 -0.40268 0.041175"
      rpy="0 0 0" />
    <parent
      link="base_link" />
    <child
      link="rotor_3_link" />
    <axis
      xyz="0 0.056997 0.99837" />
  </joint>
  <link
    name="rotor_4_link">
    <inertial>
      <origin
        xyz="-0.00095797 -0.00054628 -0.016731"
        rpy="0 0 0" />
      <mass
        value="0.021907" />
      <inertia
        ixx="1.2729E-05"
        ixy="5.7553E-06"
        ixz="8.9654E-08"
        iyy="5.57E-06"
        iyz="6.6405E-08"
        izz="1.8023E-05" />
    </inertial>
    <visual>
      <origin
        xyz="0 0 0"
        rpy="0 0 0" />
      <geometry>
        <mesh
          filename="package://myam_description/meshes/rotor_4_link.STL" />
      </geometry>
      <material
        name="">
        <color
          rgba="1 1 1 1" />
      </material>
    </visual>
    <collision>
      <origin
        xyz="0 0 0"
        rpy="0 0 0" />
      <geometry>
        <mesh
          filename="package://myam_description/meshes/rotor_4_link.STL" />
      </geometry>
    </collision>
  </link>
  <joint
    name="rotor_4_joint"
    type="continuous">
    <origin
      xyz="-0.34883 -0.2014 0.040769"
      rpy="0 0 0" />
    <parent
      link="base_link" />
    <child
      link="rotor_4_link" />
    <axis
      xyz="0.048041 0.027736 0.99846" />
  </joint>
  <link
    name="rotor_5_link">
    <inertial>
      <origin
        xyz="-0.00078667 0.00047059 -0.017046"
        rpy="0 0 0" />
      <mass
        value="0.021159" />
      <inertia
        ixx="1.0284E-05"
        ixy="-4.2421E-06"
        ixz="9.245E-08"
        iyy="4.5973E-06"
        iyz="-8.1212E-08"
        izz="1.4609E-05" />
    </inertial>
    <visual>
      <origin
        xyz="0 0 0"
        rpy="0 0 0" />
      <geometry>
        <mesh
          filename="package://myam_description/meshes/rotor_5_link.STL" />
      </geometry>
      <material
        name="">
        <color
          rgba="0.52941 0.54902 0.54902 1" />
      </material>
    </visual>
    <collision>
      <origin
        xyz="0 0 0"
        rpy="0 0 0" />
      <geometry>
        <mesh
          filename="package://myam_description/meshes/rotor_5_link.STL" />
      </geometry>
    </collision>
  </link>
  <joint
    name="rotor_5_joint"
    type="continuous">
    <origin
      xyz="-0.34873 0.20134 0.041175"
      rpy="0 0 0" />
    <parent
      link="base_link" />
    <child
      link="rotor_5_link" />
    <axis
      xyz="0.049361 -0.028499 0.99837" />
  </joint>
  <link
    name="rotor_6_link">
    <inertial>
      <origin
        xyz="4.2471E-06 0.0011028 -0.01673"
        rpy="0 0 0" />
      <mass
        value="0.021907" />
      <inertia
        ixx="2.3754E-06"
        ixy="2.222E-07"
        ixz="1.2652E-08"
        iyy="1.5929E-05"
        iyz="-1.1083E-07"
        izz="1.8028E-05" />
    </inertial>
    <visual>
      <origin
        xyz="0 0 0"
        rpy="0 0 0" />
      <geometry>
        <mesh
          filename="package://myam_description/meshes/rotor_6_link.STL" />
      </geometry>
      <material
        name="">
        <color
          rgba="1 1 1 1" />
      </material>
    </visual>
    <collision>
      <origin
        xyz="0 0 0"
        rpy="0 0 0" />
      <geometry>
        <mesh
          filename="package://myam_description/meshes/rotor_6_link.STL" />
      </geometry>
    </collision>
  </link>
  <joint
    name="rotor_6_joint"
    type="continuous">
    <origin
      xyz="0 0.4028 0.040769"
      rpy="0 0 0" />
    <parent
      link="base_link" />
    <child
      link="rotor_6_link" />
    <axis
      xyz="0 -0.055473 0.99846" />
  </joint>
  <link
    name="gps_link">
    <inertial>
      <origin
        xyz="-9.2484E-05 -7.0948E-06 -0.047946"
        rpy="0 0 0" />
      <mass
        value="0.021692" />
      <inertia
        ixx="7.1143E-06"
        ixy="1.9861E-10"
        ixz="-6.8846E-08"
        iyy="7.3732E-06"
        iyz="1.3427E-10"
        izz="7.731E-06" />
    </inertial>
    <visual>
      <origin
        xyz="0 0 0"
        rpy="0 0 0" />
      <geometry>
        <mesh
          filename="package://myam_description/meshes/gps_link.STL" />
      </geometry>
      <material
        name="">
        <color
          rgba="0.25098 0.25098 0.25098 1" />
      </material>
    </visual>
    <collision>
      <origin
        xyz="0 0 0"
        rpy="0 0 0" />
      <geometry>
        <mesh
          filename="package://myam_description/meshes/gps_link.STL" />
      </geometry>
    </collision>
  </link>
  <joint
    name="gps_joint"
    type="fixed">
    <origin
      xyz="-0.00040701 1.327E-05 0.17697"
      rpy="0 0 0" />
    <parent
      link="base_link" />
    <child
      link="gps_link" />
    <axis
      xyz="0 0 0" />
  </joint>
  <link
    name="landing_gear_1_link">
    <inertial>
      <origin
        xyz="-6.9473E-05 -0.024646 0.05428"
        rpy="0 0 0" />
      <mass
        value="0.066432" />
      <inertia
        ixx="0.00015527"
        ixy="-3.0385E-08"
        ixz="6.9106E-08"
        iyy="0.00049779"
        iyz="5.5916E-05"
        izz="0.00040082" />
    </inertial>
    <visual>
      <origin
        xyz="0 0 0"
        rpy="0 0 0" />
      <geometry>
        <mesh
          filename="package://myam_description/meshes/landing_gear_1_link.STL" />
      </geometry>
      <material
        name="">
        <color
          rgba="1 1 1 1" />
      </material>
    </visual>
    <collision>
      <origin
        xyz="0 0 0"
        rpy="0 0 0" />
      <geometry>
        <mesh
          filename="package://myam_description/meshes/landing_gear_1_link.STL" />
      </geometry>
    </collision>
  </link>
  <joint
    name="landing_gear_1_joint"
    type="fixed">
    <origin
      xyz="-1.3008E-05 0.21064 -0.40283"
      rpy="0 0 0" />
    <parent
      link="base_link" />
    <child
      link="landing_gear_1_link" />
    <axis
      xyz="0 0 0" />
  </joint>
  <link
    name="landing_gear_2_link">
    <inertial>
      <origin
        xyz="-6.9052E-05 0.024604 0.0543"
        rpy="0 0 0" />
      <mass
        value="0.066432" />
      <inertia
        ixx="0.00015527"
        ixy="3.3281E-08"
        ixz="6.8002E-08"
        iyy="0.00049778"
        iyz="-5.592E-05"
        izz="0.00040082" />
    </inertial>
    <visual>
      <origin
        xyz="0 0 0"
        rpy="0 0 0" />
      <geometry>
        <mesh
          filename="package://myam_description/meshes/landing_gear_2_link.STL" />
      </geometry>
      <material
        name="">
        <color
          rgba="1 1 1 1" />
      </material>
    </visual>
    <collision>
      <origin
        xyz="0 0 0"
        rpy="0 0 0" />
      <geometry>
        <mesh
          filename="package://myam_description/meshes/landing_gear_2_link.STL" />
      </geometry>
    </collision>
  </link>
  <joint
    name="landing_gear_2_joint"
    type="fixed">
    <origin
      xyz="-1.3008E-05 -0.21064 -0.40283"
      rpy="0 0 0" />
    <parent
      link="base_link" />
    <child
      link="landing_gear_2_link" />
    <axis
      xyz="0 0 0" />
  </joint>
  <!-- 深度相机：由 myam_sys.xacro 中 realsense_ros_gazebo 风格 D435 宏提供 camera_link 与 Gazebo 插件 -->
</xacro:macro>
</robot>
